13-Jan-21 13:11:29 - asyncio - ERROR - Task exception was never retrieved
future: <Task finished name='Task-8' coro=<Dispatcher._process_polling_updates() done, defined at /home/let/PycharmProjects/t_gold_price/venv/lib/python3.8/site-packages/aiogram/dispatcher/dispatcher.py:380> exception=FileNotFoundError(2, 'No such file or directory')>
Traceback (most recent call last):
  File "/home/let/PycharmProjects/t_gold_price/venv/lib/python3.8/site-packages/aiogram/dispatcher/dispatcher.py", line 388, in _process_polling_updates
    for responses in itertools.chain.from_iterable(await self.process_updates(updates, fast)):
  File "/home/let/PycharmProjects/t_gold_price/venv/lib/python3.8/site-packages/aiogram/dispatcher/dispatcher.py", line 225, in process_updates
    return await asyncio.gather(*tasks)
  File "/home/let/PycharmProjects/t_gold_price/venv/lib/python3.8/site-packages/aiogram/dispatcher/handler.py", line 117, in notify
    response = await handler_obj.handler(*args, **partial_data)
  File "/home/let/PycharmProjects/t_gold_price/venv/lib/python3.8/site-packages/aiogram/dispatcher/dispatcher.py", line 273, in process_update
    return await self.callback_query_handlers.notify(update.callback_query)
  File "/home/let/PycharmProjects/t_gold_price/venv/lib/python3.8/site-packages/aiogram/dispatcher/handler.py", line 117, in notify
    response = await handler_obj.handler(*args, **partial_data)
  File "/home/let/PycharmProjects/t_gold_price/handlers/main_handlers.py", line 26, in gold_choice_message
    data_from_db = get_data()
  File "/home/let/PycharmProjects/t_gold_price/bot.py", line 10, in get_data
    modified_date = datetime.datetime.fromtimestamp(os.path.getmtime(DB_FILENAME))
  File "/usr/lib/python3.8/genericpath.py", line 55, in getmtime
    return os.stat(filename).st_mtime
FileNotFoundError: [Errno 2] No such file or directory: 'datafile'
13-Jan-21 13:11:33 - asyncio - ERROR - Task exception was never retrieved
future: <Task finished name='Task-13' coro=<Dispatcher._process_polling_updates() done, defined at /home/let/PycharmProjects/t_gold_price/venv/lib/python3.8/site-packages/aiogram/dispatcher/dispatcher.py:380> exception=FileNotFoundError(2, 'No such file or directory')>
Traceback (most recent call last):
  File "/home/let/PycharmProjects/t_gold_price/venv/lib/python3.8/site-packages/aiogram/dispatcher/dispatcher.py", line 388, in _process_polling_updates
    for responses in itertools.chain.from_iterable(await self.process_updates(updates, fast)):
  File "/home/let/PycharmProjects/t_gold_price/venv/lib/python3.8/site-packages/aiogram/dispatcher/dispatcher.py", line 225, in process_updates
    return await asyncio.gather(*tasks)
  File "/home/let/PycharmProjects/t_gold_price/venv/lib/python3.8/site-packages/aiogram/dispatcher/handler.py", line 117, in notify
    response = await handler_obj.handler(*args, **partial_data)
  File "/home/let/PycharmProjects/t_gold_price/venv/lib/python3.8/site-packages/aiogram/dispatcher/dispatcher.py", line 273, in process_update
    return await self.callback_query_handlers.notify(update.callback_query)
  File "/home/let/PycharmProjects/t_gold_price/venv/lib/python3.8/site-packages/aiogram/dispatcher/handler.py", line 117, in notify
    response = await handler_obj.handler(*args, **partial_data)
  File "/home/let/PycharmProjects/t_gold_price/handlers/main_handlers.py", line 26, in gold_choice_message
    data_from_db = get_data()
  File "/home/let/PycharmProjects/t_gold_price/bot.py", line 10, in get_data
    modified_date = datetime.datetime.fromtimestamp(os.path.getmtime(DB_FILENAME))
  File "/usr/lib/python3.8/genericpath.py", line 55, in getmtime
    return os.stat(filename).st_mtime
FileNotFoundError: [Errno 2] No such file or directory: 'datafile'
13-Jan-21 13:11:35 - asyncio - ERROR - Task exception was never retrieved
future: <Task finished name='Task-17' coro=<Dispatcher._process_polling_updates() done, defined at /home/let/PycharmProjects/t_gold_price/venv/lib/python3.8/site-packages/aiogram/dispatcher/dispatcher.py:380> exception=FileNotFoundError(2, 'No such file or directory')>
Traceback (most recent call last):
  File "/home/let/PycharmProjects/t_gold_price/venv/lib/python3.8/site-packages/aiogram/dispatcher/dispatcher.py", line 388, in _process_polling_updates
    for responses in itertools.chain.from_iterable(await self.process_updates(updates, fast)):
  File "/home/let/PycharmProjects/t_gold_price/venv/lib/python3.8/site-packages/aiogram/dispatcher/dispatcher.py", line 225, in process_updates
    return await asyncio.gather(*tasks)
  File "/home/let/PycharmProjects/t_gold_price/venv/lib/python3.8/site-packages/aiogram/dispatcher/handler.py", line 117, in notify
    response = await handler_obj.handler(*args, **partial_data)
  File "/home/let/PycharmProjects/t_gold_price/venv/lib/python3.8/site-packages/aiogram/dispatcher/dispatcher.py", line 273, in process_update
    return await self.callback_query_handlers.notify(update.callback_query)
  File "/home/let/PycharmProjects/t_gold_price/venv/lib/python3.8/site-packages/aiogram/dispatcher/handler.py", line 117, in notify
    response = await handler_obj.handler(*args, **partial_data)
  File "/home/let/PycharmProjects/t_gold_price/handlers/main_handlers.py", line 26, in gold_choice_message
    data_from_db = get_data()
  File "/home/let/PycharmProjects/t_gold_price/bot.py", line 10, in get_data
    modified_date = datetime.datetime.fromtimestamp(os.path.getmtime(DB_FILENAME))
  File "/usr/lib/python3.8/genericpath.py", line 55, in getmtime
    return os.stat(filename).st_mtime
FileNotFoundError: [Errno 2] No such file or directory: 'datafile'
13-Jan-21 13:11:37 - asyncio - ERROR - Task exception was never retrieved
future: <Task finished name='Task-21' coro=<Dispatcher._process_polling_updates() done, defined at /home/let/PycharmProjects/t_gold_price/venv/lib/python3.8/site-packages/aiogram/dispatcher/dispatcher.py:380> exception=FileNotFoundError(2, 'No such file or directory')>
Traceback (most recent call last):
  File "/home/let/PycharmProjects/t_gold_price/venv/lib/python3.8/site-packages/aiogram/dispatcher/dispatcher.py", line 388, in _process_polling_updates
    for responses in itertools.chain.from_iterable(await self.process_updates(updates, fast)):
  File "/home/let/PycharmProjects/t_gold_price/venv/lib/python3.8/site-packages/aiogram/dispatcher/dispatcher.py", line 225, in process_updates
    return await asyncio.gather(*tasks)
  File "/home/let/PycharmProjects/t_gold_price/venv/lib/python3.8/site-packages/aiogram/dispatcher/handler.py", line 117, in notify
    response = await handler_obj.handler(*args, **partial_data)
  File "/home/let/PycharmProjects/t_gold_price/venv/lib/python3.8/site-packages/aiogram/dispatcher/dispatcher.py", line 273, in process_update
    return await self.callback_query_handlers.notify(update.callback_query)
  File "/home/let/PycharmProjects/t_gold_price/venv/lib/python3.8/site-packages/aiogram/dispatcher/handler.py", line 117, in notify
    response = await handler_obj.handler(*args, **partial_data)
  File "/home/let/PycharmProjects/t_gold_price/handlers/main_handlers.py", line 26, in gold_choice_message
    data_from_db = get_data()
  File "/home/let/PycharmProjects/t_gold_price/bot.py", line 10, in get_data
    modified_date = datetime.datetime.fromtimestamp(os.path.getmtime(DB_FILENAME))
  File "/usr/lib/python3.8/genericpath.py", line 55, in getmtime
    return os.stat(filename).st_mtime
FileNotFoundError: [Errno 2] No such file or directory: 'datafile'
13-Jan-21 13:11:41 - aiogram - WARNING - Goodbye!
